Workbook

Sheet wimbledons_champions
A1: Year | B1: Gender | C1: Champion | D1: Champion Nationality | E1: Champion Country | F1: Champion Seed | G1: Mins | H1: Score | I1: 1st-won | J1: 1st-loss | K1: 2nd-won | L1: 2nd-loss | M1: 3rd-won | N1: 3rd-loss | O1: 4th-won | P1: 4th-loss | Q1: 5th-won | R1: 5th-loss | S1: Runner-up | T1: Runner-up Nationality | U1: Runner-up Country | V1: Runner-up Seed
A2: 2026 | B2: Women's | C2: L. Noskova | D2: CZE | E2: Czechia | F2: 9 | G2: 148 | H2: 6-2,5-7,6-3 | I2: 6 | J2: 2 | K2: 5 | L2: 7 | M2: 6 | N2: 3 | S2: K.Muchova | T2: CZE | U2: Czechia | V2: 10
A3: 2026 | B3: Men's | C3: J. Sinner | D3: ITA | E3: Italy | F3: 1 | G3: 154 | H3: 6-7,7-6,6-3,6-4 | I3: 6 | J3: 7 | K3: 7 | L3: 6 | M3: 6 | N3: 3 | O3: 6 | P3: 4 | S3: A. Zverev | T3: GER | U3: Germany | V3: 2
A4: 2025 | B4: Women's | C4: I. Świątek | D4: POL | E4: Poland | F4: 8 | G4: 57 | H4: 6-0,6-0 | I4: 6 | J4: 0 | K4: 6 | L4: 0 | S4: A. Anisimova | T4: USA | U4: United States | V4: 13
A5: 2025 | B5: Men's | C5: J. Sinner | D5: ITA | E5: Italy | F5: 1 | G5: 184 | H5: 4-6,6-4,6-4,6-4 | I5: 4 | J5: 6 | K5: 6 | L5: 4 | M5: 6 | N5: 4 | O5: 6 | P5: 4 | S5: C. Alcaraz | T5: ESP | U5: Spain | V5: 2
A6: 2024 | B6: Women's | C6: B. Krejčíková | D6: CZE | E6: Czechia | F6: 31 | G6: 116 | H6: 6-2,2-6,6-4 | I6: 6 | J6: 2 | K6: 2 | L6: 6 | M6: 6 | N6: 4 | S6: J. Paolini | T6: ITA | U6: Italy | V6: 7
A7: 2024 | B7: Men's | C7: C. Alcaraz | D7: ESP | E7: Spain | F7: 3 | G7: 147 | H7: 6-2,6-2,7-6 | I7: 6 | J7: 2 | K7: 6 | L7: 2 | M7: 7 | N7: 6 | S7: N. Djokovic | T7: SRB | U7: Serbia | V7: 2
A8: 2023 | B8: Women's | C8: M.Vondrousova | D8: CZE | E8: Czechia | F8: U | G8: 80 | H8: 6-4, 6-4 | I8: 6 | J8: 4 | K8: 6 | L8: 4 | S8: O.Jabeur | T8: TUN | U8: Tunisia | V8: 6
A9: 2023 | B9: Men's | C9: C.Alcaraz | D9: ESP | E9: Spain | F9: 1 | G9: 283 | H9: 1-6, 7-6, 6-1, 3-6, 6-4 | I9: 1 | J9: 6 | K9: 7 | L9: 6 | M9: 6 | N9: 1 | O9: 3 | P9: 6 | Q9: 6 | R9: 4 | S9: N.Djokovic | T9: SRB | U9: Serbia | V9: 2
A10: 2022 | B10: Women's | C10: E. Rybakina | D10: KAZ | E10: Kazakhstan | F10: 17 | G10: 108 | H10: 3-6,6-2,6-2 | I10: 3 | J10: 6 | K10: 6 | L10: 5 | M10: 6 | N10: 2 | S10: O. Jabeur | T10: TUN | U10: Tunisia | V10: 3
A11: 2022 | B11: Men's | C11: N. Djokovic | D11: SRB | E11: Serbia | F11: 1 | G11: 181 | H11: 4-6,6-3,6-4,7-6(7-3) | I11: 4 | J11: 6 | K11: 6 | L11: 3 | M11: 6 | N11: 4 | O11: 7 | P11: 6 | S11: N. Kyrgios | T11: Aus | U11: Australia | V11: U
A12: 2021 | B12: Women's | C12: A. Barty | D12: AUS | E12: Australia | F12: 1 | G12: 116 | H12: 6-3,6-7(4-7),6-3 | I12: 6 | J12: 3 | K12: 6 | L12: 7 | M12: 6 | N12: 3 | S12: k.Pliskova | T12: CZE | U12: Czechia | V12: 8
A13: 2021 | B13: Men's | C13: N. Djokovic | D13: SRB | E13: Serbia | F13: 1 | G13: 204 | H13: 6-7(4-7),6-4,6-4,6-3 | I13: 6 | J13: 7 | K13: 6 | L13: 4 | M13: 6 | N13: 4 | O13: 6 | P13: 3 | S13: M. Berrettini | T13: ITA | U13: Italy | V13: 7
A14: 2019 | B14: Women's | C14: S.Halep | D14: ROU | E14: Romania | F14: 7 | G14: 56 | H14: 6-2,6-2 | I14: 6 | J14: 2 | K14: 6 | L14: 2 | S14: S. Williams | T14: USA | U14: United States | V14: 11
A15: 2019 | B15: Men's | C15: N. Djokovic | D15: SRB | E15: Serbia | F15: 1 | G15: 297 | H15: 7-6(7-5),1-6,7-6(7-4),4-6,13-12(7-3) | I15: 7 | J15: 6 | K15: 1 | L15: 6 | M15: 7 | N15: 6 | O15: 4 | P15: 6 | Q15: 7 | R15: 6 | S15: R. Federer | T15: SUI | U15: Switzerland | V15: 2
A16: 2018 | B16: Women's | C16: A. Kerber | D16: GER | E16: Germany | F16: 11 | G16: 65 | H16: 6-3,6-3 | I16: 6 | J16: 3 | K16: 6 | L16: 3 | S16: S. Williams | T16: USA | U16: United States | V16: 25
A17: 2018 | B17: Men's | C17: N. Djokovic | D17: SRB | E17: Serbia | F17: 12 | G17: 170 | H17: 6-2,6-2,7-6(7-3) | I17: 6 | J17: 2 | K17: 6 | L17: 2 | M17: 7 | N17: 6 | S17: K. Anderson | T17: RSA | U17: South Africa | V17: 8
A18: 2017 | B18: Women's | C18: G. Muguruza | D18: ESP | E18: Spain | F18: 14 | G18: 77 | H18: 7-5,6-0 | I18: 7 | J18: 5 | K18: 6 | L18: 0 | S18: V.E.S. Williams | T18: USA | U18: United States | V18: 10
A19: 2017 | B19: Men's | C19: R. Federer | D19: SUI | E19: Switzerland | F19: 3 | G19: 101 | H19: 6-3,6-1,6-4 | I19: 6 | J19: 3 | K19: 6 | L19: 1 | M19: 6 | N19: 4 | S19: M.Cilic | T19: CRO | U19: Croatia | V19: 7
A20: 2016 | B20: Women's | C20: S. Williams | D20: USA | E20: United States | F20: 1 | G20: 83 | H20: 7-5, 6-3 | I20: 7 | J20: 5 | K20: 6 | L20: 3 | S20: A. Kerber | T20: GER | U20: Germany | V20: 4
A21: 2016 | B21: Men's | C21: A. Murray | D21: GBR | E21: United Kingdom | F21: 2 | G21: 170 | H21: 6-4, 7-6(7-3), 7-6(7-2) | I21: 6 | J21: 4 | K21: 7 | L21: 6 | M21: 7 | N21: 6 | S21: M. Raonic | T21: CND | U21: Canada | V21: 6
A22: 2015 | B22: Women's | C22: S. Williams | D22: USA | E22: United States | F22: 1 | G22: 83 | H22: 6-4, 6-4 | I22: 6 | J22: 4 | K22: 6 | L22: 4 | S22: G. Muguruza | T22: ESP | U22: Spain | V22: 20
A23: 2015 | B23: Men's | C23: N. Djokovic | D23: SRB | E23: Serbia | F23: 1 | G23: 176 | H23: 7-6(7-1), 6-7(10-12), 6-4, 6-3 | I23: 7 | J23: 6 | K23: 6 | L23: 7 | M23: 6 | N23: 4 | O23: 6 | P23: 3 | S23: R. Federer | T23: SUI | U23: Switzerland | V23: 2
A24: 2014 | B24: Women's | C24: P. Kvitová | D24: CZE | E24: Czechia | F24: 6 | G24: 55 | H24: 6-3, 6-0 | I24: 6 | J24: 3 | K24: 6 | L24: 0 | S24: E. Bouchard | T24: CND | U24: Canada | V24: 13
A25: 2014 | B25: Men's | C25: N. Djokovic | D25: SRB | E25: Serbia | F25: 1 | G25: 236 | H25: 6-7(7-9), 6-4, 7-6(7-4), 5-7, 6-4 | I25: 6 | J25: 7 | K25: 6 | L25: 4 | M25: 7 | N25: 6 | O25: 5 | P25: 7 | Q25: 6 | R25: 4 | S25: R. Federer | T25: SUI | U25: Switzerland | V25: 4
A26: 2013 | B26: Women's | C26: M. Bartoli | D26: FRA | E26: France | F26: 15 | G26: 81 | H26: 6-2,1-6,6-4 | I26: 6 | J26: 2 | K26: 1 | L26: 6 | M26: 6 | N26: 4 | S26: S. Lisicki | T26: GER | U26: Germany | V26: 23
A27: 2013 | B27: Men's | C27: A. Murray | D27: GBR | E27: United Kingdom | F27: 2 | G27: 134 | H27: 6-4, 7-5, 6-4 | I27: 6 | J27: 4 | K27: 7 | L27: 5 | M27: 6 | N27: 4 | S27: N. Djokovic | T27: SRB | U27: Serbia | V27: 1
A28: 2012 | B28: Women's | C28: S. Williams | D28: USA | E28: United States | F28: 6 | G28: 122 | H28: 6-1, 5-7, 6-2 | I28: 6 | J28: 1 | K28: 5 | L28: 7 | M28: 6 | N28: 2 | S28: A. Radwańska | T28: POL | U28: Poland | V28: 3
A29: 2012 | B29: Men's | C29: R. Federer | D29: SUI | E29: Switzerland | F29: 3 | G29: 204 | H29: 4-6, 7-5, 6-3, 6-4 | I29: 4 | J29: 6 | K29: 7 | L29: 5 | M29: 6 | N29: 3 | O29: 6 | P29: 4 | S29: A. Murray | T29: GBR | U29: United Kingdom | V29: 4
A30: 2011 | B30: Women's | C30: P. Kvitova | D30: CZE | E30: Czechia | F30: 8 | G30: 85 | H30: 6-3, 6-4 | I30: 6 | J30: 3 | K30: 6 | L30: 4 | S30: M. Sharapova | T30: RUS | U30: Russia | V30: 5
A31: 2011 | B31: Men's | C31: N. Djokovic | D31: SRB | E31: Serbia | F31: 2 | G31: 148 | H31: 6-4 6-1 1-6 6-3 | I31: 6 | J31: 4 | K31: 6 | L31: 1 | M31: 1 | N31: 6 | O31: 6 | P31: 3 | S31: R. Nadal | T31: ESP | U31: Spain | V31: 1
A32: 2010 | B32: Women's | C32: S. Williams | D32: USA | E32: United States | F32: 1 | G32: 66 | H32: 6-3, 6-2 | I32: 6 | J32: 3 | K32: 6 | L32: 2 | S32: V. Zvonareva | T32: RUS | U32: Russia | V32: 21
A33: 2010 | B33: Men's | C33: R. Nadal | D33: ESP | E33: Spain | F33: 2 | G33: 133 | H33: 6-3, 7-5, 6-4 | I33: 6 | J33: 3 | K33: 7 | L33: 5 | M33: 6 | N33: 4 | S33: T. Berdych | T33: CZE | U33: Czechia | V33: 12
A34: 2009 | B34: Women's | C34: S. Williams | D34: USA | E34: United States | F34: 2 | G34: 87 | H34: 7-6 (7-3), 6-2 | I34: 7 | J34: 6 | K34: 6 | L34: 2 | S34: V.E.S. Williams | T34: USA | U34: United States | V34: 3
A35: 2009 | B35: Men's | C35: R. Federer | D35: SUI | E35: Switzerland | F35: 2 | G35: 256 | H35: 5-7, 7-6 (8-6), 7-6 (7-5), 3-6, 16-14 | I35: 5 | J35: 7 | K35: 7 | L35: 6 | M35: 7 | N35: 6 | O35: 3 | P35: 6 | Q35: 16 | R35: 14 | S35: A. Roddick | T35: USA | U35: United States | V35: 6
A36: 2008 | B36: Women's | C36: V.E.S. Williams | D36: USA | E36: United States | F36: 7 | G36: 111 | H36: 7-5, 6-4 | I36: 7 | J36: 5 | K36: 6 | L36: 4 | S36: S. Williams | T36: USA | U36: United States | V36: 6
A37: 2008 | B37: Men's | C37: R. Nadal | D37: ESP | E37: Spain | F37: 2 | G37: 288 | H37: 6-4, 6-4, 6-7 (5-7), 6-7 (8-10), 9-7 | I37: 6 | J37: 4 | K37: 6 | L37: 4 | M37: 6 | N37: 7 | O37: 6 | P37: 7 | Q37: 9 | R37: 7 | S37: R. Federer | T37: SUI | U37: Switzerland | V37: 1
A38: 2007 | B38: Women's | C38: V.E.S. Williams | D38: USA | E38: United States | F38: 23 | G38: 90 | H38: 6-4, 6-1 | I38: 6 | J38: 4 | K38: 6 | L38: 1 | S38: M. Bartoli | T38: FRA | U38: France | V38: 18
A39: 2007 | B39: Men's | C39: R. Federer | D39: SUI | E39: Switzerland | F39: 1 | G39: 225 | H39: 7-6 (9-7), 4-6, 7-6 (7-3), 2-6, 6-2 | I39: 7 | J39: 6 | K39: 4 | L39: 6 | M39: 7 | N39: 6 | O39: 2 | P39: 6 | Q39: 6 | R39: 2 | S39: R. Nadal | T39: ESP | U39: Spain | V39: 2
A40: 2006 | B40: Women's | C40: A. Mauresmo | D40: FRA | E40: France | F40: 1 | G40: 122 | H40: 2-6, 6-3, 6-4 | I40: 2 | J40: 6 | K40: 6 | L40: 3 | M40: 6 | N40: 4 | S40: PY. Hardenne | T40: BEL | U40: Belgium | V40: 3
...

Sheet Top5

Sheet Win Rate
A1: =wimbledons_champions!A1 -> Year | B1: =wimbledons_champions!B1 -> Gender | C1: Champion | D1: Champion Nationality | E1: Champion Country | F1: Champion Seed | G1: =wimbledons_champions!G1 -> Mins | H1: =wimbledons_champions!H1 -> Score | I1: Runner-up | J1: Runner-up Nationality | K1: Runner-up Country | L1: Runner-up Seed | M1: Win Rate | O1: 1st-won | P1: 1st-loss | Q1: 2nd-won | R1: 2nd-loss | S1: 3rd-won | T1: 3rd-loss | U1: 4th-won | V1: 4th-loss | W1: 5th-won | X1: 5th-loss | Y1: Win | Z1: Loss | AA1: Win Rate
A2: 2022 | B2: =wimbledons_champions!B10 -> Women's | C2: E. RYBAKINA | D2: KAZ | E2: Kazakhstan | F2: 17 | G2: 108 | H2: 3-6,6-2,6-2 | I2: O. JABEUR | J2: TUN | K2: Tunisia | L2: 3 | M2: 0.53571429 | O2: 3 | P2: 6 | Q2: 6 | R2: 5 | S2: 6 | T2: 2 | Y2: =SUM(O2+Q2+S2+U2+W2) -> 15 | Z2: =SUM(P2+R2+T2+V2+X2) -> 13 | AA2: =Y2/(Y2+Z2) -> 0.53571429
A3: 2022 | B3: =wimbledons_champions!B11 -> Men's | C3: N. Djokovic | D3: SRB | E3: Serbia | F3: 1 | G3: 181 | H3: 4-6,6-3,6-4,7-6(7-3) | I3: N. KYRGIOS | J3: Aus | K3: Australia | L3: 0 | M3: 0.54761905 | O3: 4 | P3: 6 | Q3: 6 | R3: 3 | S3: 6 | T3: 4 | U3: 7 | V3: 6 | Y3: =SUM(O3+Q3+S3+U3+W3) -> 23 | Z3: =SUM(P3+R3+T3+V3+X3) -> 19 | AA3: =Y3/(Y3+Z3) -> 0.54761905
A4: =wimbledons_champions!A12 -> 2021 | B4: =wimbledons_champions!B12 -> Women's | C4: A. Barty | D4: AUS | E4: Australia | F4: 1 | G4: =wimbledons_champions!G12 -> 116 | H4: =wimbledons_champions!H12 -> 6-3,6-7(4-7),6-3 | I4: k.Pliskova | J4: CZE | K4: Czechia | L4: 8 | M4: 0.58064516 | O4: 6 | P4: 3 | Q4: 6 | R4: 7 | S4: 6 | T4: 3 | Y4: =SUM(O4+Q4+S4+U4+W4) -> 18 | Z4: =SUM(P4+R4+T4+V4+X4) -> 13 | AA4: =Y4/(Y4+Z4) -> 0.58064516
A5: =wimbledons_champions!A13 -> 2021 | B5: =wimbledons_champions!B13 -> Men's | C5: N. Djokovic | D5: SRB | E5: Serbia | F5: 1 | G5: =wimbledons_champions!G13 -> 204 | H5: =wimbledons_champions!H13 -> 6-7(4-7),6-4,6-4,6-3 | I5: M. Berrettini | J5: ITA | K5: Italy | L5: 7 | M5: 0.57142857 | O5: 6 | P5: 7 | Q5: 6 | R5: 4 | S5: 6 | T5: 4 | U5: 6 | V5: 3 | Y5: =SUM(O5+Q5+S5+U5+W5) -> 24 | Z5: =SUM(P5+R5+T5+V5+X5) -> 18 | AA5: =Y5/(Y5+Z5) -> 0.57142857
A6: =wimbledons_champions!A14 -> 2019 | B6: =wimbledons_champions!B14 -> Women's | C6: S.Halep | D6: ROU | E6: Romania | F6: 7 | G6: =wimbledons_champions!G14 -> 56 | H6: =wimbledons_champions!H14 -> 6-2,6-2 | I6: S. Williams | J6: USA | K6: United States | L6: 11 | M6: 0.75 | O6: 6 | P6: 2 | Q6: 6 | R6: 2 | Y6: =SUM(O6+Q6+S6+U6+W6) -> 12 | Z6: =SUM(P6+R6+T6+V6+X6) -> 4 | AA6: =Y6/(Y6+Z6) -> 0.75
A7: =wimbledons_champions!A15 -> 2019 | B7: =wimbledons_champions!B15 -> Men's | C7: N. Djokovic | D7: SRB | E7: Serbia | F7: 1 | G7: =wimbledons_champions!G15 -> 297 | H7: =wimbledons_champions!H15 -> 7-6(7-5),1-6,7-6(7-4),4-6,13-12(7-3) | I7: R. Federer | J7: SUI | K7: Switzerland | L7: 2 | M7: 0.46428571 | O7: 7 | P7: 6 | Q7: 1 | R7: 6 | S7: 7 | T7: 6 | U7: 4 | V7: 6 | W7: 7 | X7: 6 | Y7: =SUM(O7+Q7+S7+U7+W7) -> 26 | Z7: =SUM(P7+R7+T7+V7+X7) -> 30 | AA7: =Y7/(Y7+Z7) -> 0.46428571
A8: =wimbledons_champions!A16 -> 2018 | B8: =wimbledons_champions!B16 -> Women's | C8: A. Kerber | D8: GER | E8: Germany | F8: 11 | G8: =wimbledons_champions!G16 -> 65 | H8: =wimbledons_champions!H16 -> 6-3,6-3 | I8: S. Williams | J8: USA | K8: United States | L8: 25 | M8: 0.66666667 | O8: 6 | P8: 3 | Q8: 6 | R8: 3 | Y8: =SUM(O8+Q8+S8+U8+W8) -> 12 | Z8: =SUM(P8+R8+T8+V8+X8) -> 6 | AA8: =Y8/(Y8+Z8) -> 0.66666667
A9: =wimbledons_champions!A17 -> 2018 | B9: =wimbledons_champions!B17 -> Men's | C9: N. Djokovic | D9: SRB | E9: Serbia | F9: 12 | G9: =wimbledons_champions!G17 -> 170 | H9: =wimbledons_champions!H17 -> 6-2,6-2,7-6(7-3) | I9: K. Anderson | J9: RSA | K9: South Africa | L9: 8 | M9: 0.65517241 | O9: 6 | P9: 2 | Q9: 6 | R9: 2 | S9: 7 | T9: 6 | Y9: =SUM(O9+Q9+S9+U9+W9) -> 19 | Z9: =SUM(P9+R9+T9+V9+X9) -> 10 | AA9: =Y9/(Y9+Z9) -> 0.65517241
A10: =wimbledons_champions!A18 -> 2017 | B10: =wimbledons_champions!B18 -> Women's | C10: G. Muguruza | D10: ESP | E10: Spain | F10: 14 | G10: =wimbledons_champions!G18 -> 77 | H10: =wimbledons_champions!H18 -> 7-5,6-0 | I10: V.E.S. Williams | J10: USA | K10: United States | L10: 10 | M10: 0.72222222 | O10: 7 | P10: 5 | Q10: 6 | R10: 0 | Y10: =SUM(O10+Q10+S10+U10+W10) -> 13 | Z10: =SUM(P10+R10+T10+V10+X10) -> 5 | AA10: =Y10/(Y10+Z10) -> 0.72222222
A11: =wimbledons_champions!A19 -> 2017 | B11: =wimbledons_champions!B19 -> Men's | C11: R. Federer | D11: SUI | E11: Switzerland | F11: 3 | G11: =wimbledons_champions!G19 -> 101 | H11: =wimbledons_champions!H19 -> 6-3,6-1,6-4 | I11: M.Cilic | J11: CRO | K11: Croatia | L11: 7 | M11: 0.69230769 | O11: 6 | P11: 3 | Q11: 6 | R11: 1 | S11: 6 | T11: 4 | Y11: =SUM(O11+Q11+S11+U11+W11) -> 18 | Z11: =SUM(P11+R11+T11+V11+X11) -> 8 | AA11: =Y11/(Y11+Z11) -> 0.69230769
A12: =wimbledons_champions!A20 -> 2016 | B12: =wimbledons_champions!B20 -> Women's | C12: S. Williams | D12: USA | E12: United States | F12: 1 | G12: =wimbledons_champions!G20 -> 83 | H12: =wimbledons_champions!H20 -> 7-5, 6-3 | I12: A. Kerber | J12: GER | K12: Germany | L12: 4 | M12: 0.61904762 | O12: 7 | P12: 5 | Q12: 6 | R12: 3 | Y12: =SUM(O12+Q12+S12+U12+W12) -> 13 | Z12: =SUM(P12+R12+T12+V12+X12) -> 8 | AA12: =Y12/(Y12+Z12) -> 0.61904762
A13: =wimbledons_champions!A21 -> 2016 | B13: =wimbledons_champions!B21 -> Men's | C13: A. Murray | D13: GBR | E13: United Kingdom | F13: 2 | G13: =wimbledons_champions!G21 -> 170 | H13: =wimbledons_champions!H21 -> 6-4, 7-6(7-3), 7-6(7-2) | I13: M. Raonic | J13: CND | K13: Canada | L13: 6 | M13: 0.55555556 | O13: 6 | P13: 4 | Q13: 7 | R13: 6 | S13: 7 | T13: 6 | Y13: =SUM(O13+Q13+S13+U13+W13) -> 20 | Z13: =SUM(P13+R13+T13+V13+X13) -> 16 | AA13: =Y13/(Y13+Z13) -> 0.55555556
A14: =wimbledons_champions!A22 -> 2015 | B14: =wimbledons_champions!B22 -> Women's | C14: S. Williams | D14: USA | E14: United States | F14: 1 | G14: =wimbledons_champions!G22 -> 83 | H14: =wimbledons_champions!H22 -> 6-4, 6-4 | I14: G. Muguruza | J14: ESP | K14: Spain | L14: 20 | M14: 0.6 | O14: 6 | P14: 4 | Q14: 6 | R14: 4 | Y14: =SUM(O14+Q14+S14+U14+W14) -> 12 | Z14: =SUM(P14+R14+T14+V14+X14) -> 8 | AA14: =Y14/(Y14+Z14) -> 0.6
A15: =wimbledons_champions!A23 -> 2015 | B15: =wimbledons_champions!B23 -> Men's | C15: N. Djokovic | D15: SRB | E15: Serbia | F15: 1 | G15: =wimbledons_champions!G23 -> 176 | H15: =wimbledons_champions!H23 -> 7-6(7-1), 6-7(10-12), 6-4, 6-3 | I15: R. Federer | J15: SUI | K15: Switzerland | L15: 2 | M15: 0.55555556 | O15: 7 | P15: 6 | Q15: 6 | R15: 7 | S15: 6 | T15: 4 | U15: 6 | V15: 3 | Y15: =SUM(O15+Q15+S15+U15+W15) -> 25 | Z15: =SUM(P15+R15+T15+V15+X15) -> 20 | AA15: =Y15/(Y15+Z15) -> 0.55555556
A16: =wimbledons_champions!A24 -> 2014 | B16: =wimbledons_champions!B24 -> Women's | C16: P. Kvitová | D16: CZE | E16: Czechia | F16: 6 | G16: =wimbledons_champions!G24 -> 55 | H16: =wimbledons_champions!H24 -> 6-3, 6-0 | I16: E. Bouchard | J16: CND | K16: Canada | L16: 13 | M16: 0.8 | O16: 6 | P16: 3 | Q16: 6 | R16: 0 | Y16: =SUM(O16+Q16+S16+U16+W16) -> 12 | Z16: =SUM(P16+R16+T16+V16+X16) -> 3 | AA16: =Y16/(Y16+Z16) -> 0.8
A17: =wimbledons_champions!A25 -> 2014 | B17: =wimbledons_champions!B25 -> Men's | C17: N. Djokovic | D17: SRB | E17: Serbia | F17: 1 | G17: =wimbledons_champions!G25 -> 236 | H17: =wimbledons_champions!H25 -> 6-7(7-9), 6-4, 7-6(7-4), 5-7, 6-4 | I17: R. Federer | J17: SUI | K17: Switzerland | L17: 4 | M17: 0.51724138 | O17: 6 | P17: 7 | Q17: 6 | R17: 4 | S17: 7 | T17: 6 | U17: 5 | V17: 7 | W17: 6 | X17: 4 | Y17: =SUM(O17+Q17+S17+U17+W17) -> 30 | Z17: =SUM(P17+R17+T17+V17+X17) -> 28 | AA17: =Y17/(Y17+Z17) -> 0.51724138
A18: =wimbledons_champions!A26 -> 2013 | B18: =wimbledons_champions!B26 -> Women's | C18: M. Bartoli | D18: FRA | E18: France | F18: 15 | G18: =wimbledons_champions!G26 -> 81 | H18: =wimbledons_champions!H26 -> 6-2,1-6,6-4 | I18: S. Lisicki | J18: GER | K18: Germany | L18: 23 | M18: 0.52 | O18: 6 | P18: 2 | Q18: 1 | R18: 6 | S18: 6 | T18: 4 | Y18: =SUM(O18+Q18+S18+U18+W18) -> 13 | Z18: =SUM(P18+R18+T18+V18+X18) -> 12 | AA18: =Y18/(Y18+Z18) -> 0.52
A19: =wimbledons_champions!A27 -> 2013 | B19: =wimbledons_champions!B27 -> Men's | C19: A. Murray | D19: GBR | E19: United Kingdom | F19: 2 | G19: =wimbledons_champions!G27 -> 134 | H19: =wimbledons_champions!H27 -> 6-4, 7-5, 6-4 | I19: N. Djokovic | J19: SRB | K19: Serbia | L19: 1 | M19: 0.59375 | O19: 6 | P19: 4 | Q19: 7 | R19: 5 | S19: 6 | T19: 4 | Y19: =SUM(O19+Q19+S19+U19+W19) -> 19 | Z19: =SUM(P19+R19+T19+V19+X19) -> 13 | AA19: =Y19/(Y19+Z19) -> 0.59375
A20: =wimbledons_champions!A28 -> 2012 | B20: =wimbledons_champions!B28 -> Women's | C20: S. Williams | D20: USA | E20: United States | F20: 6 | G20: =wimbledons_champions!G28 -> 122 | H20: =wimbledons_champions!H28 -> 6-1, 5-7, 6-2 | I20: A. Radwańska | J20: POL | K20: Poland | L20: 3 | M20: 0.62962963 | O20: 6 | P20: 1 | Q20: 5 | R20: 7 | S20: 6 | T20: 2 | Y20: =SUM(O20+Q20+S20+U20+W20) -> 17 | Z20: =SUM(P20+R20+T20+V20+X20) -> 10 | AA20: =Y20/(Y20+Z20) -> 0.62962963
A21: =wimbledons_champions!A29 -> 2012 | B21: =wimbledons_champions!B29 -> Men's | C21: R. Federer | D21: SUI | E21: Switzerland | F21: 3 | G21: =wimbledons_champions!G29 -> 204 | H21: =wimbledons_champions!H29 -> 4-6, 7-5, 6-3, 6-4 | I21: A. Murray | J21: GBR | K21: United Kingdom | L21: 4 | M21: 0.56097561 | O21: 4 | P21: 6 | Q21: 7 | R21: 5 | S21: 6 | T21: 3 | U21: 6 | V21: 4 | Y21: =SUM(O21+Q21+S21+U21+W21) -> 23 | Z21: =SUM(P21+R21+T21+V21+X21) -> 18 | AA21: =Y21/(Y21+Z21) -> 0.56097561
A22: =wimbledons_champions!A30 -> 2011 | B22: =wimbledons_champions!B30 -> Women's | C22: P. Kvitova | D22: CZE | E22: Czechia | F22: 8 | G22: =wimbledons_champions!G30 -> 85 | H22: =wimbledons_champions!H30 -> 6-3, 6-4 | I22: M. Sharapova | J22: RUS | K22: Russia | L22: 5 | M22: 0.63157895 | O22: 6 | P22: 3 | Q22: 6 | R22: 4 | Y22: =SUM(O22+Q22+S22+U22+W22) -> 12 | Z22: =SUM(P22+R22+T22+V22+X22) -> 7 | AA22: =Y22/(Y22+Z22) -> 0.63157895
A23: =wimbledons_champions!A31 -> 2011 | B23: =wimbledons_champions!B31 -> Men's | C23: N. Djokovic | D23: SRB | E23: Serbia | F23: 2 | G23: =wimbledons_champions!G31 -> 148 | H23: =wimbledons_champions!H31 -> 6-4 6-1 1-6 6-3 | I23: R. Nadal | J23: ESP | K23: Spain | L23: 1 | M23: 0.57575758 | O23: 6 | P23: 4 | Q23: 6 | R23: 1 | S23: 1 | T23: 6 | U23: 6 | V23: 3 | Y23: =SUM(O23+Q23+S23+U23+W23) -> 19 | Z23: =SUM(P23+R23+T23+V23+X23) -> 14 | AA23: =Y23/(Y23+Z23) -> 0.57575758
A24: =wimbledons_champions!A32 -> 2010 | B24: =wimbledons_champions!B32 -> Women's | C24: S. Williams | D24: USA | E24: United States | F24: 1 | G24: =wimbledons_champions!G32 -> 66 | H24: =wimbledons_champions!H32 -> 6-3, 6-2 | I24: V. Zvonareva | J24: RUS | K24: Russia | L24: 21 | M24: 0.70588235 | O24: 6 | P24: 3 | Q24: 6 | R24: 2 | Y24: =SUM(O24+Q24+S24+U24+W24) -> 12 | Z24: =SUM(P24+R24+T24+V24+X24) -> 5 | AA24: =Y24/(Y24+Z24) -> 0.70588235
A25: =wimbledons_champions!A33 -> 2010 | B25: =wimbledons_champions!B33 -> Men's | C25: R. Nadal | D25: ESP | E25: Spain | F25: 2 | G25: =wimbledons_champions!G33 -> 133 | H25: =wimbledons_champions!H33 -> 6-3, 7-5, 6-4 | I25: T. Berdych | J25: CZE | K25: Czechia | L25: 12 | M25: 0.61290323 | O25: 6 | P25: 3 | Q25: 7 | R25: 5 | S25: 6 | T25: 4 | Y25: =SUM(O25+Q25+S25+U25+W25) -> 19 | Z25: =SUM(P25+R25+T25+V25+X25) -> 12 | AA25: =Y25/(Y25+Z25) -> 0.61290323
A26: =wimbledons_champions!A34 -> 2009 | B26: =wimbledons_champions!B34 -> Women's | C26: S. Williams | D26: USA | E26: United States | F26: 2 | G26: =wimbledons_champions!G34 -> 87 | H26: =wimbledons_champions!H34 -> 7-6 (7-3), 6-2 | I26: V.E.S. Williams | J26: USA | K26: United States | L26: 3 | M26: 0.61904762 | O26: 7 | P26: 6 | Q26: 6 | R26: 2 | Y26: =SUM(O26+Q26+S26+U26+W26) -> 13 | Z26: =SUM(P26+R26+T26+V26+X26) -> 8 | AA26: =Y26/(Y26+Z26) -> 0.61904762
A27: =wimbledons_champions!A35 -> 2009 | B27: =wimbledons_champions!B35 -> Men's | C27: R. Federer | D27: SUI | E27: Switzerland | F27: 2 | G27: =wimbledons_champions!G35 -> 256 | H27: =wimbledons_champions!H35 -> 5-7, 7-6 (8-6), 7-6 (7-5), 3-6, 16-14 | I27: A. Roddick | J27: USA | K27: United States | L27: 6 | M27: 0.49350649 | O27: 5 | P27: 7 | Q27: 7 | R27: 6 | S27: 7 | T27: 6 | U27: 3 | V27: 6 | W27: 16 | X27: 14 | Y27: =SUM(O27+Q27+S27+U27+W27) -> 38 | Z27: =SUM(P27+R27+T27+V27+X27) -> 39 | AA27: =Y27/(Y27+Z27) -> 0.49350649
A28: =wimbledons_champions!A36 -> 2008 | B28: =wimbledons_champions!B36 -> Women's | C28: V.E.S. Williams | D28: USA | E28: United States | F28: 7 | G28: =wimbledons_champions!G36 -> 111 | H28: =wimbledons_champions!H36 -> 7-5, 6-4 | I28: S. Williams | J28: USA | K28: United States | L28: 6 | M28: 0.59090909 | O28: 7 | P28: 5 | Q28: 6 | R28: 4 | Y28: =SUM(O28+Q28+S28+U28+W28) -> 13 | Z28: =SUM(P28+R28+T28+V28+X28) -> 9 | AA28: =Y28/(Y28+Z28) -> 0.59090909
A29: =wimbledons_champions!A37 -> 2008 | B29: =wimbledons_champions!B37 -> Men's | C29: R. Nadal | D29: ESP | E29: Spain | F29: 2 | G29: =wimbledons_champions!G37 -> 288 | H29: =wimbledons_champions!H37 -> 6-4, 6-4, 6-7 (5-7), 6-7 (8-10), 9-7 | I29: R. Federer | J29: SUI | K29: Switzerland | L29: 1 | M29: 0.53225806 | O29: 6 | P29: 4 | Q29: 6 | R29: 4 | S29: 6 | T29: 7 | U29: 6 | V29: 7 | W29: 9 | X29: 7 | Y29: =SUM(O29+Q29+S29+U29+W29) -> 33 | Z29: =SUM(P29+R29+T29+V29+X29) -> 29 | AA29: =Y29/(Y29+Z29) -> 0.53225806
A30: =wimbledons_champions!A38 -> 2007 | B30: =wimbledons_champions!B38 -> Women's | C30: V.E.S. Williams | D30: USA | E30: United States | F30: 23 | G30: =wimbledons_champions!G38 -> 90 | H30: =wimbledons_champions!H38 -> 6-4, 6-1 | I30: M. Bartoli | J30: FRA | K30: France | L30: 18 | M30: 0.70588235 | O30: 6 | P30: 4 | Q30: 6 | R30: 1 | Y30: =SUM(O30+Q30+S30+U30+W30) -> 12 | Z30: =SUM(P30+R30+T30+V30+X30) -> 5 | AA30: =Y30/(Y30+Z30) -> 0.70588235
A31: =wimbledons_champions!A39 -> 2007 | B31: =wimbledons_champions!B39 -> Men's | C31: R. Federer | D31: SUI | E31: Switzerland | F31: 1 | G31: =wimbledons_champions!G39 -> 225 | H31: =wimbledons_champions!H39 -> 7-6 (9-7), 4-6, 7-6 (7-3), 2-6, 6-2 | I31: R. Nadal | J31: ESP | K31: Spain | L31: 2 | M31: 0.5 | O31: 7 | P31: 6 | Q31: 4 | R31: 6 | S31: 7 | T31: 6 | U31: 2 | V31: 6 | W31: 6 | X31: 2 | Y31: =SUM(O31+Q31+S31+U31+W31) -> 26 | Z31: =SUM(P31+R31+T31+V31+X31) -> 26 | AA31: =Y31/(Y31+Z31) -> 0.5
A32: =wimbledons_champions!A40 -> 2006 | B32: =wimbledons_champions!B40 -> Women's | C32: A. Mauresmo | D32: FRA | E32: France | F32: 1 | G32: =wimbledons_champions!G40 -> 122 | H32: =wimbledons_champions!H40 -> 2-6, 6-3, 6-4 | I32: PY. Hardenne | J32: BEL | K32: Belgium | L32: 3 | M32: 0.51851852 | O32: 2 | P32: 6 | Q32: 6 | R32: 3 | S32: 6 | T32: 4 | Y32: =SUM(O32+Q32+S32+U32+W32) -> 14 | Z32: =SUM(P32+R32+T32+V32+X32) -> 13 | AA32: =Y32/(Y32+Z32) -> 0.51851852
A33: =wimbledons_champions!A41 -> 2006 | B33: =wimbledons_champions!B41 -> Men's | C33: R. Federer | D33: SUI | E33: Switzerland | F33: 1 | G33: =wimbledons_champions!G41 -> 170 | H33: =wimbledons_champions!H41 -> 6-0, 7-6 (7-5), 6-7 (2-7), 6-3 | I33: R. Nadal | J33: ESP | K33: Spain | L33: 2 | M33: 0.6097561 | O33: 6 | P33: 0 | Q33: 7 | R33: 6 | S33: 6 | T33: 7 | U33: 6 | V33: 3 | Y33: =SUM(O33+Q33+S33+U33+W33) -> 25 | Z33: =SUM(P33+R33+T33+V33+X33) -> 16 | AA33: =Y33/(Y33+Z33) -> 0.6097561
A34: =wimbledons_champions!A42 -> 2005 | B34: =wimbledons_champions!B42 -> Women's | C34: V.E.S. Williams | D34: USA | E34: United States | F34: 14 | G34: =wimbledons_champions!G42 -> 166 | H34: =wimbledons_champions!H42 -> 4-6, 7-6 (7-4), 9-7 | I34: L.A. Davenport | J34: USA | K34: United States | L34: 1 | M34: 0.51282051 | O34: 4 | P34: 6 | Q34: 7 | R34: 6 | S34: 9 | T34: 7 | Y34: =SUM(O34+Q34+S34+U34+W34) -> 20 | Z34: =SUM(P34+R34+T34+V34+X34) -> 19 | AA34: =Y34/(Y34+Z34) -> 0.51282051
A35: =wimbledons_champions!A43 -> 2005 | B35: =wimbledons_champions!B43 -> Men's | C35: R. Federer | D35: SUI | E35: Switzerland | F35: 1 | G35: =wimbledons_champions!G43 -> 101 | H35: =wimbledons_champions!H43 -> 6-2, 7-6 (7-2), 6-4 | I35: A. Roddick | J35: USA | K35: United States | L35: 2 | M35: 0.61290323 | O35: 6 | P35: 2 | Q35: 7 | R35: 6 | S35: 6 | T35: 4 | Y35: =SUM(O35+Q35+S35+U35+W35) -> 19 | Z35: =SUM(P35+R35+T35+V35+X35) -> 12 | AA35: =Y35/(Y35+Z35) -> 0.61290323
A36: =wimbledons_champions!A44 -> 2004 | B36: =wimbledons_champions!B44 -> Women's | C36: M. Sharapova | D36: RUS | E36: Russia | F36: 13 | G36: =wimbledons_champions!G44 -> 74 | H36: =wimbledons_champions!H44 -> 6-1, 6-4 | I36: S. Williams | J36: USA | K36: United States | L36: 1 | M36: 0.70588235 | O36: 6 | P36: 1 | Q36: 6 | R36: 4 | Y36: =SUM(O36+Q36+S36+U36+W36) -> 12 | Z36: =SUM(P36+R36+T36+V36+X36) -> 5 | AA36: =Y36/(Y36+Z36) -> 0.70588235
A37: =wimbledons_champions!A45 -> 2004 | B37: =wimbledons_champions!B45 -> Men's | C37: R. Federer | D37: SUI | E37: Switzerland | F37: 1 | G37: =wimbledons_champions!G45 -> 151 | H37: =wimbledons_champions!H45 -> 4-6, 7-5, 7-6 (7-3), 6-4 | I37: A. Roddick | J37: USA | K37: United States | L37: 2 | M37: 0.53333333 | O37: 4 | P37: 6 | Q37: 7 | R37: 5 | S37: 7 | T37: 6 | U37: 6 | V37: 4 | Y37: =SUM(O37+Q37+S37+U37+W37) -> 24 | Z37: =SUM(P37+R37+T37+V37+X37) -> 21 | AA37: =Y37/(Y37+Z37) -> 0.53333333
A38: =wimbledons_champions!A46 -> 2003 | B38: =wimbledons_champions!B46 -> Women's | C38: S. Williams | D38: USA | E38: United States | F38: 1 | G38: =wimbledons_champions!G46 -> 123 | H38: =wimbledons_champions!H46 -> 4-6, 6-4, 6-2 | I38: V.E.S. Williams | J38: USA | K38: United States | L38: 4 | M38: 0.57142857 | O38: 4 | P38: 6 | Q38: 6 | R38: 4 | S38: 6 | T38: 2 | Y38: =SUM(O38+Q38+S38+U38+W38) -> 16 | Z38: =SUM(P38+R38+T38+V38+X38) -> 12 | AA38: =Y38/(Y38+Z38) -> 0.57142857
A39: =wimbledons_champions!A47 -> 2003 | B39: =wimbledons_champions!B47 -> Men's | C39: R. Federer | D39: SUI | E39: Switzerland | F39: 4 | G39: =wimbledons_champions!G47 -> 119 | H39: =wimbledons_champions!H47 -> 7-6 (7-5), 6-2, 7-6 (7-3) | I39: M. Philippousis | J39: AUS | K39: Australia | L39: U | M39: 0.58823529 | O39: 7 | P39: 6 | Q39: 6 | R39: 2 | S39: 7 | T39: 6 | Y39: =SUM(O39+Q39+S39+U39+W39) -> 20 | Z39: =SUM(P39+R39+T39+V39+X39) -> 14 | AA39: =Y39/(Y39+Z39) -> 0.58823529
A40: =wimbledons_champions!A48 -> 2002 | B40: =wimbledons_champions!B48 -> Women's | C40: S. Williams | D40: USA | E40: United States | F40: 2 | G40: =wimbledons_champions!G48 -> 78 | H40: =wimbledons_champions!H48 -> 7-6 (7-4), 6-3 | I40: V.E.S. Williams | J40: USA | K40: United States | L40: 1 | M40: 0.59090909 | O40: 7 | P40: 6 | Q40: 6 | R40: 3 | Y40: =SUM(O40+Q40+S40+U40+W40) -> 13 | Z40: =SUM(P40+R40+T40+V40+X40) -> 9 | AA40: =Y40/(Y40+Z40) -> 0.59090909
...

Sheet Map
A1: Year | B1: Gender | C1: Champion | D1: Champion Nationality | E1: Champion Country | F1: Champion Seed | G1: Mins | H1: Score | I1: Runner-up | J1: Runner-up Nationality | K1: Runner-up Country | L1: Runner-up Seed
A2: 2019 | B2: Women's | C2: S.Halep | D2: ROU | E2: Romania | F2: 7 | G2: 56 | H2: 6-2,6-2 | I2: S. Williams | J2: USA | K2: United States | L2: 11
A3: 2019 | B3: Men's | C3: N. Djokovic | D3: SRB | E3: Serbia | F3: 1 | G3: 297 | H3: 7-6,1-6,7-6,4-6,7-6 | I3: R. Federer | J3: SUI | K3: Switzerland | L3: 2
A4: 2018 | B4: Women's | C4: A.Kerber | D4: GER | E4: Germany | F4: 11 | G4: 65 | H4: 6-3,6-3 | I4: S. Williams | J4: USA | K4: United States | L4: 25
A5: 2018 | B5: Men's | C5: N. Djokovic | D5: SRB | E5: Serbia | F5: 12 | G5: 170 | H5: 6-2,6-2,7-6 | I5: K.Anderson | J5: RSA | K5: South Africa | L5: 8
A6: 2017 | B6: Women's | C6: G.Muguruza | D6: ESP | E6: Spain | F6: 14 | G6: 77 | H6: 7-5,6-0 | I6: V.E.S Williams | J6: USA | K6: United States | L6: 10
A7: 2017 | B7: Men's | C7: R. Federer | D7: SUI | E7: Switzerland | F7: 3 | G7: 101 | H7: 6-3,6-1,6-4 | I7: M.Cilic | J7: HRV | K7: Croatiaatia | L7: 7
A8: 2016 | B8: Women's | C8: S. Williams | D8: USA | E8: United States | F8: 1 | G8: 83 | H8: 7-5, 6-3 | I8: A. Kerber | J8: GER | K8: Germany | L8: 4
A9: 2016 | B9: Men's | C9: A. Murray | D9: GBR | E9: United Kingdom | F9: 2 | G9: 170 | H9: 6-4, 7-6, 7-6 | I9: M. Raonic | J9: CND | K9: Canada | L9: 6
A10: 2015 | B10: Women's | C10: S. Williams | D10: USA | E10: United States | F10: 1 | G10: 83 | H10: 6-4, 6-4 | I10: G. Muguruza | J10: ESP | K10: Spain | L10: 20
A11: 2015 | B11: Men's | C11: N. Djokovic | D11: SRB | E11: Serbia | F11: 1 | G11: 176 | H11: 7-6, 6-7, 6-4, 6-3 | I11: R. Federer | J11: SUI | K11: Switzerland | L11: 2
A12: 2014 | B12: Women's | C12: P. Kvitová | D12: CZE | E12: Czechia | F12: 6 | G12: 55 | H12: 6-3, 6-0 | I12: E. Bouchard | J12: CND | K12: Canada | L12: 13
A13: 2014 | B13: Men's | C13: N. Djokovic | D13: SRB | E13: Serbia | F13: 1 | G13: 236 | H13: 6-7, 6-4, 7-64, 5-7, 6-4 | I13: R. Federer | J13: SUI | K13: Switzerland | L13: 4
... A34: 2003 | B34: Women's | C34: S. Williams | D34: USA | E34: United States | F34: 1 | G34: 123 | H34: 4-6, 6-4, 6-2 | I34: V.E.S. Williams | J34: USA | K34: United States | L34: 4
A35: 2003 | B35: Men's | C35: R. Federer | D35: SUI | E35: Switzerland | F35: 4 | G35: 119 | H35: 7-6 (7-5), 6-2, 7-6 (7-3) | I35: M. Philippousis | J35: AUS | K35: Australia | L35: U
A36: 2002 | B36: Women's | C36: S. Williams | D36: USA | E36: United States | F36: 2 | G36: 78 | H36: 7-6 (7-4), 6-3 | I36: V.E.S. Williams | J36: USA | K36: United States | L36: 1
A37: 2002 | B37: Men's | C37: L.G. Hewitt | D37: AUS | E37: Australia | F37: 1 | G37: 116 | H37: 6-1, 6-3, 6-2 | I37: D.P. Nalbandian | J37: ARG | K37: Argentina | L37: 28
A38: 2001 | B38: Women's | C38: V.E.S. Williams | D38: USA | E38: United States | F38: 2 | G38: 69 | H38: 6-1, 3-6, 6-0 | I38: J. Henin | J38: BEL | K38: Belgium | L38: 8
A39: 2001 | B39: Men's | C39: G.S. Ivanisevic | D39: CRO | E39: Croatia | G39: 182 | H39: 6-3, 3-6, 6-3, 2-6, 9-7 | I39: P.M. Rafter | J39: AUS | K39: Australia | L39: 3
A40: 2000 | B40: Women's | C40: V.E.S. Williams | D40: USA | E40: United States | F40: 5 | G40: 84 | H40: 6-3, 7-6 (7-3) | I40: L.A. Davenport | J40: USA | K40: United States | L40: 2
A41: 2000 | B41: Men's | C41: P. Sampras | D41: USA | E41: United States | F41: 1 | G41: 182 | H41: 6-7 (10-12), 7-6 (7-5), 6-4, 6-2 | I41: P.M. Rafter | J41: AUS | K41: Australia | L41: 12
A42: 1999 | B42: Women's | C42: L.A. Davenport | D42: USA | E42: United States | F42: 3 | G42: 75 | H42: 6-4, 7-5 | I42: S.M. Graf | J42: GER | K42: Germany | L42: 2
A43: 1999 | B43: Men's | C43: P. Sampras | D43: USA | E43: United States | F43: 1 | G43: 115 | H43: 6-3, 6-4, 7-5 | I43: A.K. Agassi | J43: USA | K43: United States | L43: 4
A44: 1998 | B44: Women's | C44: J. Novotna | D44: CZE | E44: Czechia | F44: 3 | G44: 94 | H44: 6-4, 7-6 (7-2) | I44: N. Tauziat | J44: FRA | K44: France | L44: 16
A45: 1998 | B45: Men's | C45: P. Sampras | D45: USA | E45: United States | F45: 1 | G45: 172 | H45: 6-7 (2-7), 7-6 (11-9), 6-4, 3-6, 6-2 | I45: G.S. Ivanisevic | J45: CRO | K45: Croatia | L45: 14
A46: 1997 | B46: Women's | C46: M. Hingis | D46: SUI | E46: Switzerland | F46: 1 | G46: 110 | H46: 2-6, 6-3, 6-3 | I46: J. Novotna | J46: CZE | K46: Czechia | L46: 3
A47: 1997 | B47: Men's | C47: P. Sampras | D47: USA | E47: United States | F47: 1 | G47: 94 | H47: 6-4, 6-2, 6-4 | I47: C.A. Pioline | J47: FRA | K47: France | L47: U
A48: 1996 | B48: Women's | C48: S.M. Graf | D48: GER | E48: Germany | F48: 1 | G48: 88 | H48: 6-3, 7-5, | I48: A.I.M. Sanchez Vicario | J48: ESP | K48: Spain | L48: 4
A49: 1996 | B49: Men's | C49: R.P.S. Krajicek | D49: NED | E49: Netherlands | G49: 94 | H49: 6-3, 6-4, 6-3 | I49: M.O. Washington | J49: USA | K49: United States | L49: U
A50: 1995 | B50: Women's | C50: S.M. Graf | D50: GER | E50: Germany | F50: 1 | G50: 122 | H50: 4-6, 6-1, 7-5, | I50: A.I.M. Sanchez Vicario | J50: ESP | K50: Spain | L50: 2
A51: 1995 | B51: Men's | C51: P. Sampras | D51: USA | E51: United States | F51: 2 | G51: 149 | H51: 6-7 (5-7), 6-2, 6-4, 6-2 | I51: B.F. Becker | J51: GER | K51: Germany | L51: 3
A52: 1994 | B52: Women's | C52: I.C. Martinez | D52: ESP | E52: Spain | F52: 3 | G52: 119 | H52: 6-4, 3-6, 6-3, | I52: M. Navratilova | J52: USA | K52: United States | L52: 4
A53: 1994 | B53: Men's | C53: P. Sampras | D53: USA | E53: United States | F53: 1 | G53: 115 | H53: 7-6 (7-2), 7-6 (7-5), 6-0 | I53: G.S. Ivanisevic | J53: CRO | K53: Croatia | L53: 4
A54: 1993 | B54: Women's | C54: S.M. Graf | D54: GER | E54: Germany | F54: 1 | G54: 134 | H54: 7-6 (8-6), 1-6, 6-4, | I54: J. Novotna | J54: CZE | K54: Czechia | L54: 8
A55: 1993 | B55: Men's | C55: P. Sampras | D55: USA | E55: United States | F55: 1 | G55: 178 | H55: 7-6 (7-3), 7-6 (8-6), 3-6, 6-3 | I55: J.S. Courier | J55: USA | K55: United States | L55: 3
A56: 1992 | B56: Women's | C56: S.M. Graf | D56: GER | E56: Germany | F56: 2 | G56: 58 | H56: 6-2, 6-1, | I56: M. Seles | J56: YUG | K56: Yugoslavia | L56: 1
A57: 1992 | B57: Men's | C57: A.K. Agassi | D57: USA | E57: United States | F57: 12 | G57: 170 | H57: 6-7 (8-10), 6-4, 6-4, 1-6, 6-4 | I57: G.S. Ivanisevic | J57: CRO | K57: Croatia | L57: 8
A58: 1991 | B58: Women's | C58: S.M. Graf | D58: GER | E58: Germany | F58: 1 | G58: 127 | H58: 6-4, 3-6, 8-6, | I58: G.B. Sabatini | J58: ARG | K58: Argentina | L58: 2
A59: 1991 | B59: Men's | C59: M.D. Stich | D59: GER | E59: Germany | F59: 6 | G59: 153 | H59: 6-4, 7-6 (7-4), 6-4 | I59: B.F. Becker | J59: GER | K59: Germany | L59: 2
A60: 1990 | B60: Women's | C60: M. Navratilova | D60: USA | E60: United States | F60: 2 | G60: 75 | H60: 6-4, 6-1, | I60: Z.L. Garrison | J60: USA | K60: United States | L60: 5
...

Sheet visual pattern
A1: Year | B1: Gender | C1: Champion | D1: Champion Seed | E1: Mins | F1: Score | G1: Runner-up | H1: Runner-up Seed
A2: 2019 | B2: Women's | C2: S.Halep | D2: 7 | E2: 56 | F2: 6-2,6-2 | G2: S. Williams | H2: 11
A3: 2019 | B3: Men's | C3: N. Djokovic | D3: 1 | E3: 297 | F3: 7-6,1-6,7-6,4-6,7-6 | G3: R. Federer | H3: 2
A4: 2018 | B4: Women's | C4: A.Kerber | D4: 11 | E4: 65 | F4: 6-3,6-3 | G4: S. Williams | H4: 25
A5: 2018 | B5: Men's | C5: N. Djokovic | D5: 12 | E5: 170 | F5: 6-2,6-2,7-6 | G5: K.Anderson | H5: 8
A6: 2017 | B6: Women's | C6: G.Muguruza | D6: 14 | E6: 77 | F6: 7-5,6-0 | G6: V.E.S Williams | H6: 10
A7: 2017 | B7: Men's | C7: R. Federer | D7: 3 | E7: 101 | F7: 6-3,6-1,6-4 | G7: M.Cilic | H7: 7
A8: 2016 | B8: Women's | C8: S. Williams | D8: 1 | E8: 83 | F8: 7-5, 6-3 | G8: A. Kerber | H8: 4
A9: 2016 | B9: Men's | C9: A. Murray | D9: 2 | E9: 170 | F9: 6-4, 7-6, 7-6 | G9: M. Raonic | H9: 6
A10: 2015 | B10: Women's | C10: S. Williams | D10: 1 | E10: 83 | F10: 6-4, 6-4 | G10: G. Muguruza | H10: 20
A11: 2015 | B11: Men's | C11: N. Djokovic | D11: 1 | E11: 176 | F11: 7-6, 6-7, 6-4, 6-3 | G11: R. Federer | H11: 2
A12: 2014 | B12: Women's | C12: P. Kvitová | D12: 6 | E12: 55 | F12: 6-3, 6-0 | G12: E. Bouchard | H12: 13
A13: 2014 | B13: Men's | C13: N. Djokovic | D13: 1 | E13: 236 | F13: 6-7, 6-4, 7-64, 5-7, 6-4 | G13: R. Federer | H13: 4
... A34: 2003 | B34: Women's | C34: S. Williams | D34: 1 | E34: 123 | F34: 4-6, 6-4, 6-2 | G34: V.E.S. Williams | H34: 4
A35: 2003 | B35: Men's | C35: R. Federer | D35: 4 | E35: 119 | F35: 7-6 (7-5), 6-2, 7-6 (7-3) | G35: M. Philippousis | H35: U
A36: 2002 | B36: Women's | C36: S. Williams | D36: 2 | E36: 78 | F36: 7-6 (7-4), 6-3 | G36: V.E.S. Williams | H36: 1
A37: 2002 | B37: Men's | C37: L.G. Hewitt | D37: 1 | E37: 116 | F37: 6-1, 6-3, 6-2 | G37: D.P. Nalbandian | H37: 28
A38: 2001 | B38: Women's | C38: V.E.S. Williams | D38: 2 | E38: 69 | F38: 6-1, 3-6, 6-0 | G38: J. Henin | H38: 8
A39: 2001 | B39: Men's | C39: G.S. Ivanisevic | E39: 182 | F39: 6-3, 3-6, 6-3, 2-6, 9-7 | G39: P.M. Rafter | H39: 3
A40: 2000 | B40: Women's | C40: V.E.S. Williams | D40: 5 | E40: 84 | F40: 6-3, 7-6 (7-3) | G40: L.A. Davenport | H40: 2
A41: 2000 | B41: Men's | C41: P. Sampras | D41: 1 | E41: 182 | F41: 6-7 (10-12), 7-6 (7-5), 6-4, 6-2 | G41: P.M. Rafter | H41: 12
A42: 1999 | B42: Women's | C42: L.A. Davenport | D42: 3 | E42: 75 | F42: 6-4, 7-5 | G42: S.M. Graf | H42: 2
A43: 1999 | B43: Men's | C43: P. Sampras | D43: 1 | E43: 115 | F43: 6-3, 6-4, 7-5 | G43: A.K. Agassi | H43: 4
A44: 1998 | B44: Women's | C44: J. Novotna | D44: 3 | E44: 94 | F44: 6-4, 7-6 (7-2) | G44: N. Tauziat | H44: 16
A45: 1998 | B45: Men's | C45: P. Sampras | D45: 1 | E45: 172 | F45: 6-7 (2-7), 7-6 (11-9), 6-4, 3-6, 6-2 | G45: G.S. Ivanisevic | H45: 14
A46: 1997 | B46: Women's | C46: M. Hingis | D46: 1 | E46: 110 | F46: 2-6, 6-3, 6-3 | G46: J. Novotna | H46: 3
A47: 1997 | B47: Men's | C47: P. Sampras | D47: 1 | E47: 94 | F47: 6-4, 6-2, 6-4 | G47: C.A. Pioline | H47: U
A48: 1996 | B48: Women's | C48: S.M. Graf | D48: 1 | E48: 88 | F48: 6-3, 7-5, | G48: A.I.M. Sanchez Vicario | H48: 4
A49: 1996 | B49: Men's | C49: R.P.S. Krajicek | E49: 94 | F49: 6-3, 6-4, 6-3 | G49: M.O. Washington | H49: U
A50: 1995 | B50: Women's | C50: S.M. Graf | D50: 1 | E50: 122 | F50: 4-6, 6-1, 7-5, | G50: A.I.M. Sanchez Vicario | H50: 2
A51: 1995 | B51: Men's | C51: P. Sampras | D51: 2 | E51: 149 | F51: 6-7 (5-7), 6-2, 6-4, 6-2 | G51: B.F. Becker | H51: 3
A52: 1994 | B52: Women's | C52: I.C. Martinez | D52: 3 | E52: 119 | F52: 6-4, 3-6, 6-3, | G52: M. Navratilova | H52: 4
A53: 1994 | B53: Men's | C53: P. Sampras | D53: 1 | E53: 115 | F53: 7-6 (7-2), 7-6 (7-5), 6-0 | G53: G.S. Ivanisevic | H53: 4
A54: 1993 | B54: Women's | C54: S.M. Graf | D54: 1 | E54: 134 | F54: 7-6 (8-6), 1-6, 6-4, | G54: J. Novotna | H54: 8
A55: 1993 | B55: Men's | C55: P. Sampras | D55: 1 | E55: 178 | F55: 7-6 (7-3), 7-6 (8-6), 3-6, 6-3 | G55: J.S. Courier | H55: 3
A56: 1992 | B56: Women's | C56: S.M. Graf | D56: 2 | E56: 58 | F56: 6-2, 6-1, | G56: M. Seles | H56: 1
A57: 1992 | B57: Men's | C57: A.K. Agassi | D57: 12 | E57: 170 | F57: 6-7 (8-10), 6-4, 6-4, 1-6, 6-4 | G57: G.S. Ivanisevic | H57: 8
A58: 1991 | B58: Women's | C58: S.M. Graf | D58: 1 | E58: 127 | F58: 6-4, 3-6, 8-6, | G58: G.B. Sabatini | H58: 2
A59: 1991 | B59: Men's | C59: M.D. Stich | D59: 6 | E59: 153 | F59: 6-4, 7-6 (7-4), 6-4 | G59: B.F. Becker | H59: 2
A60: 1990 | B60: Women's | C60: M. Navratilova | D60: 2 | E60: 75 | F60: 6-4, 6-1, | G60: Z.L. Garrison | H60: 5
...

Sheet Math
A1: =wimbledons_champions!A1 -> Year | B1: =wimbledons_champions!B1 -> Gender | C1: =wimbledons_champions!C1 -> Champion | D1: =wimbledons_champions!D1 -> Champion Nationality | E1: =wimbledons_champions!F1 -> Champion Seed | F1: =wimbledons_champions!G1 -> Mins | G1: =wimbledons_champions!H1 -> Score | H1: =wimbledons_champions!S1 -> Runner-up | I1: =wimbledons_champions!T1 -> Runner-up Nationality | J1: =wimbledons_champions!V1 -> Runner-up Seed
A2: =wimbledons_champions!A14 -> 2019 | B2: =wimbledons_champions!B14 -> Women's | C2: =wimbledons_champions!C14 -> S.Halep | D2: =wimbledons_champions!D14 -> ROU | E2: =wimbledons_champions!F14 -> 7 | F2: =wimbledons_champions!G14 -> 56 | G2: =wimbledons_champions!H14 -> 6-2,6-2 | H2: =wimbledons_champions!S14 -> S. Williams | I2: =wimbledons_champions!T14 -> USA | J2: =wimbledons_champions!V14 -> 11
A3: =wimbledons_champions!A15 -> 2019 | B3: =wimbledons_champions!B15 -> Men's | C3: =wimbledons_champions!C15 -> N. Djokovic | D3: =wimbledons_champions!D15 -> SRB | E3: =wimbledons_champions!F15 -> 1 | F3: =wimbledons_champions!G15 -> 297 | G3: =wimbledons_champions!H15 -> 7-6(7-5),1-6,7-6(7-4),4-6,13-12(7-3) | H3: =wimbledons_champions!S15 -> R. Federer | I3: =wimbledons_champions!T15 -> SUI | J3: =wimbledons_champions!V15 -> 2
A4: =wimbledons_champions!A16 -> 2018 | B4: =wimbledons_champions!B16 -> Women's | C4: =wimbledons_champions!C16 -> A. Kerber | D4: =wimbledons_champions!D16 -> GER | E4: =wimbledons_champions!F16 -> 11 | F4: =wimbledons_champions!G16 -> 65 | G4: =wimbledons_champions!H16 -> 6-3,6-3 | H4: =wimbledons_champions!S16 -> S. Williams | I4: =wimbledons_champions!T16 -> USA | J4: =wimbledons_champions!V16 -> 25
A5: =wimbledons_champions!A17 -> 2018 | B5: =wimbledons_champions!B17 -> Men's | C5: =wimbledons_champions!C17 -> N. Djokovic | D5: =wimbledons_champions!D17 -> SRB | E5: =wimbledons_champions!F17 -> 12 | F5: =wimbledons_champions!G17 -> 170 | G5: =wimbledons_champions!H17 -> 6-2,6-2,7-6(7-3) | H5: =wimbledons_champions!S17 -> K. Anderson | I5: =wimbledons_champions!T17 -> RSA | J5: =wimbledons_champions!V17 -> 8
A6: =wimbledons_champions!A18 -> 2017 | B6: =wimbledons_champions!B18 -> Women's | C6: =wimbledons_champions!C18 -> G. Muguruza | D6: =wimbledons_champions!D18 -> ESP | E6: =wimbledons_champions!F18 -> 14 | F6: =wimbledons_champions!G18 -> 77 | G6: =wimbledons_champions!H18 -> 7-5,6-0 | H6: =wimbledons_champions!S18 -> V.E.S. Williams | I6: =wimbledons_champions!T18 -> USA | J6: =wimbledons_champions!V18 -> 10
A7: =wimbledons_champions!A19 -> 2017 | B7: =wimbledons_champions!B19 -> Men's | C7: =wimbledons_champions!C19 -> R. Federer | D7: =wimbledons_champions!D19 -> SUI | E7: =wimbledons_champions!F19 -> 3 | F7: =wimbledons_champions!G19 -> 101 | G7: =wimbledons_champions!H19 -> 6-3,6-1,6-4 | H7: =wimbledons_champions!S19 -> M.Cilic | I7: =wimbledons_champions!T19 -> CRO | J7: =wimbledons_champions!V19 -> 7
A8: =wimbledons_champions!A20 -> 2016 | B8: =wimbledons_champions!B20 -> Women's | C8: =wimbledons_champions!C20 -> S. Williams | D8: =wimbledons_champions!D20 -> USA | E8: =wimbledons_champions!F20 -> 1 | F8: =wimbledons_champions!G20 -> 83 | G8: =wimbledons_champions!H20 -> 7-5, 6-3 | H8: =wimbledons_champions!S20 -> A. Kerber | I8: =wimbledons_champions!T20 -> GER | J8: =wimbledons_champions!V20 -> 4
A9: =wimbledons_champions!A21 -> 2016 | B9: =wimbledons_champions!B21 -> Men's | C9: =wimbledons_champions!C21 -> A. Murray | D9: =wimbledons_champions!D21 -> GBR | E9: =wimbledons_champions!F21 -> 2 | F9: =wimbledons_champions!G21 -> 170 | G9: =wimbledons_champions!H21 -> 6-4, 7-6(7-3), 7-6(7-2) | H9: =wimbledons_champions!S21 -> M. Raonic | I9: =wimbledons_champions!T21 -> CND | J9: =wimbledons_champions!V21 -> 6
A10: =wimbledons_champions!A22 -> 2015 | B10: =wimbledons_champions!B22 -> Women's | C10: =wimbledons_champions!C22 -> S. Williams | D10: =wimbledons_champions!D22 -> USA | E10: =wimbledons_champions!F22 -> 1 | F10: =wimbledons_champions!G22 -> 83 | G10: =wimbledons_champions!H22 -> 6-4, 6-4 | H10: =wimbledons_champions!S22 -> G. Muguruza | I10: =wimbledons_champions!T22 -> ESP | J10: =wimbledons_champions!V22 -> 20
A11: =wimbledons_champions!A23 -> 2015 | B11: =wimbledons_champions!B23 -> Men's | C11: =wimbledons_champions!C23 -> N. Djokovic | D11: =wimbledons_champions!D23 -> SRB | E11: =wimbledons_champions!F23 -> 1 | F11: =wimbledons_champions!G23 -> 176 | G11: =wimbledons_champions!H23 -> 7-6(7-1), 6-7(10-12), 6-4, 6-3 | H11: =wimbledons_champions!S23 -> R. Federer | I11: =wimbledons_champions!T23 -> SUI | J11: =wimbledons_champions!V23 -> 2
A12: =wimbledons_champions!A24 -> 2014 | B12: =wimbledons_champions!B24 -> Women's | C12: =wimbledons_champions!C24 -> P. Kvitová | D12: =wimbledons_champions!D24 -> CZE | E12: =wimbledons_champions!F24 -> 6 | F12: =wimbledons_champions!G24 -> 55 | G12: =wimbledons_champions!H24 -> 6-3, 6-0 | H12: =wimbledons_champions!S24 -> E. Bouchard | I12: =wimbledons_champions!T24 -> CND | J12: =wimbledons_champions!V24 -> 13
A13: =wimbledons_champions!A25 -> 2014 | B13: =wimbledons_champions!B25 -> Men's | C13: =wimbledons_champions!C25 -> N. Djokovic | D13: =wimbledons_champions!D25 -> SRB | E13: =wimbledons_champions!F25 -> 1 | F13: =wimbledons_champions!G25 -> 236 | G13: =wimbledons_champions!H25 -> 6-7(7-9), 6-4, 7-6(7-4), 5-7, 6-4 | H13: =wimbledons_champions!S25 -> R. Federer | I13: =wimbledons_champions!T25 -> SUI | J13: =wimbledons_champions!V25 -> 4
... A260: =wimbledons_champions!A272 -> 1877 | B260: =wimbledons_champions!B272 -> Men's | C260: =wimbledons_champions!C272 -> S.W. Gore | D260: =wimbledons_champions!D272 -> GBR | E260: =wimbledons_champions!F272 -> 0 | F260: =wimbledons_champions!G272 -> 48 | G260: =wimbledons_champions!H272 -> 6-1, 6-2, 6-4 | H260: =wimbledons_champions!S272 -> W.C. Marshall | I260: =wimbledons_champions!T272 -> GBR | J260: =wimbledons_champions!V272 -> 0
B263: total | C263: 124 | D263: 16 | E263: =AVERAGE(E2:E175) -> 2.8596491 | F263: 101 | H263: 167 | I263: 27
B267: men's | C267: 65 | F267: 119
B268: women | C268: 59 | F268: 78.6
A271: =8/(8+4) -> 0.66666667 | B271: Men | C271: R. Federer win rate 8 to 4 | D271: SUI
A272: =9/(9+6) -> 0.6 | B272: Woman | C272: M. Navratilova win rate 9 to 3 | D272: USA

Sheet treemap
A1: Year | B1: Gender | C1: Champion | D1: Champion Nationality | E1: Champion Seed | F1: Mins | G1: Score | H1: Runner-up | I1: Runner-up Nationality | J1: Runner-up Seed
A2: 2019 | B2: Women's | C2: S.Halep | D2: ROU | E2: 7 | F2: 56 | G2: 6-2,6-2 | H2: S. Williams | I2: USA | J2: 11
A3: 2019 | B3: Men's | C3: N. Djokovic | D3: SRB | E3: 1 | F3: 297 | G3: 7-6,1-6,7-6,4-6,7-6 | H3: R. Federer | I3: SUI | J3: 2
A4: 2018 | B4: Women's | C4: A.Kerber | D4: GER | E4: 11 | F4: 65 | G4: 6-3,6-3 | H4: S. Williams | I4: USA | J4: 25
A5: 2018 | B5: Men's | C5: N. Djokovic | D5: SRB | E5: 12 | F5: 170 | G5: 6-2,6-2,7-6 | H5: K.Anderson | I5: RSA | J5: 8
A6: 2017 | B6: Women's | C6: G.Muguruza | D6: ESP | E6: 14 | F6: 77 | G6: 7-5,6-0 | H6: V.E.S Williams | I6: USA | J6: 10
A7: 2017 | B7: Men's | C7: R. Federer | D7: SUI | E7: 3 | F7: 101 | G7: 6-3,6-1,6-4 | H7: M.Cilic | I7: HRV | J7: 7
A8: 2016 | B8: Women's | C8: S. Williams | D8: USA | E8: 1 | F8: 83 | G8: 7-5, 6-3 | H8: A. Kerber | I8: GER | J8: 4
A9: 2016 | B9: Men's | C9: A. Murray | D9: GBR | E9: 2 | F9: 170 | G9: 6-4, 7-6, 7-6 | H9: M. Raonic | I9: CND | J9: 6
A10: 2015 | B10: Women's | C10: S. Williams | D10: USA | E10: 1 | F10: 83 | G10: 6-4, 6-4 | H10: G. Muguruza | I10: ESP | J10: 20
A11: 2015 | B11: Men's | C11: N. Djokovic | D11: SRB | E11: 1 | F11: 176 | G11: 7-6, 6-7, 6-4, 6-3 | H11: R. Federer | I11: SUI | J11: 2
A12: 2014 | B12: Women's | C12: P. Kvitová | D12: CZE | E12: 6 | F12: 55 | G12: 6-3, 6-0 | H12: E. Bouchard | I12: CND | J12: 13
A13: 2014 | B13: Men's | C13: N. Djokovic | D13: SRB | E13: 1 | F13: 236 | G13: 6-7, 6-4, 7-64, 5-7, 6-4 | H13: R. Federer | I13: SUI | J13: 4
... A34: 2003 | B34: Women's | C34: S. Williams | D34: USA | E34: 1 | F34: 123 | G34: 4-6, 6-4, 6-2 | H34: V.E.S. Williams | I34: USA | J34: 4
A35: 2003 | B35: Men's | C35: R. Federer | D35: SUI | E35: 4 | F35: 119 | G35: 7-6 (7-5), 6-2, 7-6 (7-3) | H35: M. Philippousis | I35: AUS | J35: U
A36: 2002 | B36: Women's | C36: S. Williams | D36: USA | E36: 2 | F36: 78 | G36: 7-6 (7-4), 6-3 | H36: V.E.S. Williams | I36: USA | J36: 1
A37: 2002 | B37: Men's | C37: L.G. Hewitt | D37: AUS | E37: 1 | F37: 116 | G37: 6-1, 6-3, 6-2 | H37: D.P. Nalbandian | I37: ARG | J37: 28
A38: 2001 | B38: Women's | C38: V.E.S. Williams | D38: USA | E38: 2 | F38: 69 | G38: 6-1, 3-6, 6-0 | H38: J. Henin | I38: BEL | J38: 8
A39: 2001 | B39: Men's | C39: G.S. Ivanisevic | D39: CRO | F39: 182 | G39: 6-3, 3-6, 6-3, 2-6, 9-7 | H39: P.M. Rafter | I39: AUS | J39: 3
A40: 2000 | B40: Women's | C40: V.E.S. Williams | D40: USA | E40: 5 | F40: 84 | G40: 6-3, 7-6 (7-3) | H40: L.A. Davenport | I40: USA | J40: 2
A41: 2000 | B41: Men's | C41: P. Sampras | D41: USA | E41: 1 | F41: 182 | G41: 6-7 (10-12), 7-6 (7-5), 6-4, 6-2 | H41: P.M. Rafter | I41: AUS | J41: 12
A42: 1999 | B42: Women's | C42: L.A. Davenport | D42: USA | E42: 3 | F42: 75 | G42: 6-4, 7-5 | H42: S.M. Graf | I42: GER | J42: 2
A43: 1999 | B43: Men's | C43: P. Sampras | D43: USA | E43: 1 | F43: 115 | G43: 6-3, 6-4, 7-5 | H43: A.K. Agassi | I43: USA | J43: 4
A44: 1998 | B44: Women's | C44: J. Novotna | D44: CZE | E44: 3 | F44: 94 | G44: 6-4, 7-6 (7-2) | H44: N. Tauziat | I44: FRA | J44: 16
A45: 1998 | B45: Men's | C45: P. Sampras | D45: USA | E45: 1 | F45: 172 | G45: 6-7 (2-7), 7-6 (11-9), 6-4, 3-6, 6-2 | H45: G.S. Ivanisevic | I45: CRO | J45: 14
A46: 1997 | B46: Women's | C46: M. Hingis | D46: SUI | E46: 1 | F46: 110 | G46: 2-6, 6-3, 6-3 | H46: J. Novotna | I46: CZE | J46: 3
A47: 1997 | B47: Men's | C47: P. Sampras | D47: USA | E47: 1 | F47: 94 | G47: 6-4, 6-2, 6-4 | H47: C.A. Pioline | I47: FRA | J47: U
A48: 1996 | B48: Women's | C48: S.M. Graf | D48: GER | E48: 1 | F48: 88 | G48: 6-3, 7-5, | H48: A.I.M. Sanchez Vicario | I48: ESP | J48: 4
A49: 1996 | B49: Men's | C49: R.P.S. Krajicek | D49: NED | F49: 94 | G49: 6-3, 6-4, 6-3 | H49: M.O. Washington | I49: USA | J49: U
A50: 1995 | B50: Women's | C50: S.M. Graf | D50: GER | E50: 1 | F50: 122 | G50: 4-6, 6-1, 7-5, | H50: A.I.M. Sanchez Vicario | I50: ESP | J50: 2
A51: 1995 | B51: Men's | C51: P. Sampras | D51: USA | E51: 2 | F51: 149 | G51: 6-7 (5-7), 6-2, 6-4, 6-2 | H51: B.F. Becker | I51: GER | J51: 3
A52: 1994 | B52: Women's | C52: I.C. Martinez | D52: ESP | E52: 3 | F52: 119 | G52: 6-4, 3-6, 6-3, | H52: M. Navratilova | I52: USA | J52: 4
A53: 1994 | B53: Men's | C53: P. Sampras | D53: USA | E53: 1 | F53: 115 | G53: 7-6 (7-2), 7-6 (7-5), 6-0 | H53: G.S. Ivanisevic | I53: CRO | J53: 4
A54: 1993 | B54: Women's | C54: S.M. Graf | D54: GER | E54: 1 | F54: 134 | G54: 7-6 (8-6), 1-6, 6-4, | H54: J. Novotna | I54: CZE | J54: 8
A55: 1993 | B55: Men's | C55: P. Sampras | D55: USA | E55: 1 | F55: 178 | G55: 7-6 (7-3), 7-6 (8-6), 3-6, 6-3 | H55: J.S. Courier | I55: USA | J55: 3
A56: 1992 | B56: Women's | C56: S.M. Graf | D56: GER | E56: 2 | F56: 58 | G56: 6-2, 6-1, | H56: M. Seles | I56: YUG | J56: 1
A57: 1992 | B57: Men's | C57: A.K. Agassi | D57: USA | E57: 12 | F57: 170 | G57: 6-7 (8-10), 6-4, 6-4, 1-6, 6-4 | H57: G.S. Ivanisevic | I57: CRO | J57: 8
A58: 1991 | B58: Women's | C58: S.M. Graf | D58: GER | E58: 1 | F58: 127 | G58: 6-4, 3-6, 8-6, | H58: G.B. Sabatini | I58: ARG | J58: 2
A59: 1991 | B59: Men's | C59: M.D. Stich | D59: GER | E59: 6 | F59: 153 | G59: 6-4, 7-6 (7-4), 6-4 | H59: B.F. Becker | I59: GER | J59: 2
A60: 1990 | B60: Women's | C60: M. Navratilova | D60: USA | E60: 2 | F60: 75 | G60: 6-4, 6-1, | H60: Z.L. Garrison | I60: USA | J60: 5
...

Sheet Text Cloud
A1: Champion | B1: Champion Nationality | C1: Score | D1: Runner-up | E1: Runner-up Nationality
A2: S.Halep | B2: ROU | C2: 6-2,6-2 | D2: S. Williams | E2: USA
A3: N. Djokovic | B3: SRB | C3: 7-6,1-6,7-6,4-6,7-6 | D3: R. Federer | E3: SUI
A4: A.Kerber | B4: GER | C4: 6-3,6-3 | D4: S. Williams | E4: USA
A5: N. Djokovic | B5: SRB | C5: 6-2,6-2,7-6 | D5: K.Anderson | E5: RSA
A6: G.Muguruza | B6: ESP | C6: 7-5,6-0 | D6: V.E.S Williams | E6: USA
A7: R. Federer | B7: SUI | C7: 6-3,6-1,6-4 | D7: M.Cilic | E7: HRV
A8: A. Murray | B8: GBR | C8: 6-4, 7-6, 7-6 | D8: M. Raonic | E8: CND
A9: S. Williams | B9: USA | C9: 7-5, 6-3 | D9: A. Kerber | E9: GER
A10: N. Djokovic | B10: SRB | C10: 7-6, 6-7, 6-4, 6-3 | D10: R. Federer | E10: SUI
A11: S. Williams | B11: USA | C11: 6-4, 6-4 | D11: G. Muguruza | E11: ESP
A12: P. Kvitová | B12: CZE | C12: 6-3, 6-0 | D12: E. Bouchard | E12: CND
... A260: S.W. Gore | B260: GBR | C260: 6-1, 6-2, 6-4 | D260: W.C. Marshall | E260: GBR

Sheet Match-country
A1: Year | B1: Men's Champion Nationality | C1: Women's Champion Nationality
A2: 2019 | B2: SRB | C2: ROU
A3: 2018 | B3: SRB | C3: GER
A4: 2017 | B4: SUI | C4: ESP
A5: 2016 | B5: GBR | C5: USA
A6: 2015 | B6: SRB | C6: USA
A7: 2014 | B7: SRB | C7: CZE
A8: 2013 | B8: GBR | C8: FRA
A9: 2012 | B9: SUI | C9: USA
A10: 2011 | B10: SRB | C10: CZE
A11: 2010 | B11: ESP | C11: USA
A12: 2009 | B12: SUI | C12: USA
A13: 2008 | B13: ESP | C13: USA
... A127: 1884 | B127: GBR | C127: GBR
A128: 1883 | B128: GBR
A129: 1882 | B129: GBR
A130: 1881 | B130: GBR
A131: 1880 | B131: GBR
A132: 1879 | B132: GBR
A133: 1878 | B133: GBR
A134: 1877 | B134: GBR

Sheet Men-1
A1: =wimbledons_champions!A1 -> Year | B1: =wimbledons_champions!B1 -> Gender | C1: =wimbledons_champions!C1 -> Champion | D1: =wimbledons_champions!D1 -> Champion Nationality | E1: =wimbledons_champions!F1 -> Champion Seed | F1: =wimbledons_champions!G1 -> Mins | G1: =wimbledons_champions!H1 -> Score | H1: =wimbledons_champions!S1 -> Runner-up | I1: =wimbledons_champions!T1 -> Runner-up Nationality | J1: =wimbledons_champions!V1 -> Runner-up Seed
A2: 2021 | B2: Men's | C2: N. Djokovic | D2: SRB | E2: 1 | F2: 204 | G2: 6-7,6-4,6-4,6-3 | H2: M. Berrettini | I2: ITA | J2: 7
A3: =wimbledons_champions!A15 -> 2019 | B3: =wimbledons_champions!B15 -> Men's | C3: =wimbledons_champions!C15 -> N. Djokovic | D3: =wimbledons_champions!D15 -> SRB | E3: =wimbledons_champions!F15 -> 1 | F3: =wimbledons_champions!G15 -> 297 | G3: =wimbledons_champions!H15 -> 7-6(7-5),1-6,7-6(7-4),4-6,13-12(7-3) | H3: =wimbledons_champions!S15 -> R. Federer | I3: =wimbledons_champions!T15 -> SUI | J3: =wimbledons_champions!V15 -> 2
A4: =wimbledons_champions!A17 -> 2018 | B4: =wimbledons_champions!B17 -> Men's | C4: =wimbledons_champions!C17 -> N. Djokovic | D4: =wimbledons_champions!D17 -> SRB | E4: =wimbledons_champions!F17 -> 12 | F4: =wimbledons_champions!G17 -> 170 | G4: =wimbledons_champions!H17 -> 6-2,6-2,7-6(7-3) | H4: =wimbledons_champions!S17 -> K. Anderson | I4: =wimbledons_champions!T17 -> RSA | J4: =wimbledons_champions!V17 -> 8
A5: =wimbledons_champions!A19 -> 2017 | B5: =wimbledons_champions!B19 -> Men's | C5: =wimbledons_champions!C19 -> R. Federer | D5: =wimbledons_champions!D19 -> SUI | E5: =wimbledons_champions!F19 -> 3 | F5: =wimbledons_champions!G19 -> 101 | G5: =wimbledons_champions!H19 -> 6-3,6-1,6-4 | H5: =wimbledons_champions!S19 -> M.Cilic | I5: =wimbledons_champions!T19 -> CRO | J5: =wimbledons_champions!V19 -> 7
A6: =wimbledons_champions!A21 -> 2016 | B6: =wimbledons_champions!B21 -> Men's | C6: =wimbledons_champions!C21 -> A. Murray | D6: =wimbledons_champions!D21 -> GBR | E6: =wimbledons_champions!F21 -> 2 | F6: =wimbledons_champions!G21 -> 170 | G6: =wimbledons_champions!H21 -> 6-4, 7-6(7-3), 7-6(7-2) | H6: =wimbledons_champions!S21 -> M. Raonic | I6: =wimbledons_champions!T21 -> CND | J6: =wimbledons_champions!V21 -> 6
A7: =wimbledons_champions!A23 -> 2015 | B7: =wimbledons_champions!B23 -> Men's | C7: =wimbledons_champions!C23 -> N. Djokovic | D7: =wimbledons_champions!D23 -> SRB | E7: =wimbledons_champions!F23 -> 1 | F7: =wimbledons_champions!G23 -> 176 | G7: =wimbledons_champions!H23 -> 7-6(7-1), 6-7(10-12), 6-4, 6-3 | H7: =wimbledons_champions!S23 -> R. Federer | I7: =wimbledons_champions!T23 -> SUI | J7: =wimbledons_champions!V23 -> 2
A8: =wimbledons_champions!A25 -> 2014 | B8: =wimbledons_champions!B25 -> Men's | C8: =wimbledons_champions!C25 -> N. Djokovic | D8: =wimbledons_champions!D25 -> SRB | E8: =wimbledons_champions!F25 -> 1 | F8: =wimbledons_champions!G25 -> 236 | G8: =wimbledons_champions!H25 -> 6-7(7-9), 6-4, 7-6(7-4), 5-7, 6-4 | H8: =wimbledons_champions!S25 -> R. Federer | I8: =wimbledons_champions!T25 -> SUI | J8: =wimbledons_champions!V25 -> 4
A9: =wimbledons_champions!A27 -> 2013 | B9: =wimbledons_champions!B27 -> Men's | C9: =wimbledons_champions!C27 -> A. Murray | D9: =wimbledons_champions!D27 -> GBR | E9: =wimbledons_champions!F27 -> 2 | F9: =wimbledons_champions!G27 -> 134 | G9: =wimbledons_champions!H27 -> 6-4, 7-5, 6-4 | H9: =wimbledons_champions!S27 -> N. Djokovic | I9: =wimbledons_champions!T27 -> SRB | J9: =wimbledons_champions!V27 -> 1
A10: =wimbledons_champions!A29 -> 2012 | B10: =wimbledons_champions!B29 -> Men's | C10: =wimbledons_champions!C29 -> R. Federer | D10: =wimbledons_champions!D29 -> SUI | E10: =wimbledons_champions!F29 -> 3 | F10: =wimbledons_champions!G29 -> 204 | G10: =wimbledons_champions!H29 -> 4-6, 7-5, 6-3, 6-4 | H10: =wimbledons_champions!S29 -> A. Murray | I10: =wimbledons_champions!T29 -> GBR | J10: =wimbledons_champions!V29 -> 4
A11: =wimbledons_champions!A31 -> 2011 | B11: =wimbledons_champions!B31 -> Men's | C11: =wimbledons_champions!C31 -> N. Djokovic | D11: =wimbledons_champions!D31 -> SRB | E11: =wimbledons_champions!F31 -> 2 | F11: =wimbledons_champions!G31 -> 148 | G11: =wimbledons_champions!H31 -> 6-4 6-1 1-6 6-3 | H11: =wimbledons_champions!S31 -> R. Nadal | I11: =wimbledons_champions!T31 -> ESP | J11: =wimbledons_champions!V31 -> 1
A12: =wimbledons_champions!A33 -> 2010 | B12: =wimbledons_champions!B33 -> Men's | C12: =wimbledons_champions!C33 -> R. Nadal | D12: =wimbledons_champions!D33 -> ESP | E12: =wimbledons_champions!F33 -> 2 | F12: =wimbledons_champions!G33 -> 133 | G12: =wimbledons_champions!H33 -> 6-3, 7-5, 6-4 | H12: =wimbledons_champions!S33 -> T. Berdych | I12: =wimbledons_champions!T33 -> CZE | J12: =wimbledons_champions!V33 -> 12
A13: =wimbledons_champions!A35 -> 2009 | B13: =wimbledons_champions!B35 -> Men's | C13: =wimbledons_champions!C35 -> R. Federer | D13: =wimbledons_champions!D35 -> SUI | E13: =wimbledons_champions!F35 -> 2 | F13: =wimbledons_champions!G35 -> 256 | G13: =wimbledons_champions!H35 -> 5-7, 7-6 (8-6), 7-6 (7-5), 3-6, 16-14 | H13: =wimbledons_champions!S35 -> A. Roddick | I13: =wimbledons_champions!T35 -> USA | J13: =wimbledons_champions!V35 -> 6
A14: =wimbledons_champions!A37 -> 2008 | B14: =wimbledons_champions!B37 -> Men's | C14: =wimbledons_champions!C37 -> R. Nadal | D14: =wimbledons_champions!D37 -> ESP | E14: =wimbledons_champions!F37 -> 2 | F14: =wimbledons_champions!G37 -> 288 | G14: =wimbledons_champions!H37 -> 6-4, 6-4, 6-7 (5-7), 6-7 (8-10), 9-7 | H14: =wimbledons_champions!S37 -> R. Federer | I14: =wimbledons_champions!T37 -> SUI | J14: =wimbledons_champions!V37 -> 1
A15: =wimbledons_champions!A39 -> 2007 | B15: =wimbledons_champions!B39 -> Men's | C15: =wimbledons_champions!C39 -> R. Federer | D15: =wimbledons_champions!D39 -> SUI | E15: =wimbledons_champions!F39 -> 1 | F15: =wimbledons_champions!G39 -> 225 | G15: =wimbledons_champions!H39 -> 7-6 (9-7), 4-6, 7-6 (7-3), 2-6, 6-2 | H15: =wimbledons_champions!S39 -> R. Nadal | I15: =wimbledons_champions!T39 -> ESP | J15: =wimbledons_champions!V39 -> 2
A16: =wimbledons_champions!A41 -> 2006 | B16: =wimbledons_champions!B41 -> Men's | C16: =wimbledons_champions!C41 -> R. Federer | D16: =wimbledons_champions!D41 -> SUI | E16: =wimbledons_champions!F41 -> 1 | F16: =wimbledons_champions!G41 -> 170 | G16: =wimbledons_champions!H41 -> 6-0, 7-6 (7-5), 6-7 (2-7), 6-3 | H16: =wimbledons_champions!S41 -> R. Nadal | I16: =wimbledons_champions!T41 -> ESP | J16: =wimbledons_champions!V41 -> 2
A17: =wimbledons_champions!A43 -> 2005 | B17: =wimbledons_champions!B43 -> Men's | C17: =wimbledons_champions!C43 -> R. Federer | D17: =wimbledons_champions!D43 -> SUI | E17: =wimbledons_champions!F43 -> 1 | F17: =wimbledons_champions!G43 -> 101 | G17: =wimbledons_champions!H43 -> 6-2, 7-6 (7-2), 6-4 | H17: =wimbledons_champions!S43 -> A. Roddick | I17: =wimbledons_champions!T43 -> USA | J17: =wimbledons_champions!V43 -> 2
A18: =wimbledons_champions!A45 -> 2004 | B18: =wimbledons_champions!B45 -> Men's | C18: =wimbledons_champions!C45 -> R. Federer | D18: =wimbledons_champions!D45 -> SUI | E18: =wimbledons_champions!F45 -> 1 | F18: =wimbledons_champions!G45 -> 151 | G18: =wimbledons_champions!H45 -> 4-6, 7-5, 7-6 (7-3), 6-4 | H18: =wimbledons_champions!S45 -> A. Roddick | I18: =wimbledons_champions!T45 -> USA | J18: =wimbledons_champions!V45 -> 2
